# Promise 对象

## 前言

在异步编程中，Promise 扮演了举足轻重的角色，它解决了 ajax 请求过程中的回调地狱的问题，令代码更具可读性。

`Promise`对象有以下两处特点：

- 对象的状态不受外界影响。`Promise`对象代表一个异步操作，有三种状态：`pending`（进行中）、`fulfilled`（已成功）和`rejected`（已失败）。只有异步操作的结果，可以决定当前是哪一种状态，任何其他操作都无法改变这个状态。这也是`Promise`这个名字的由来，它的英语意思就是“承诺”，表示其他手段无法改变。
- 一旦状态改变，就不会再变，任何时候都可以得到这个结果。`Promise`对象的状态改变，只有两种可能：从`pending`变为`fulfilled`和从`pending`变为`rejected`。只要这两种情况发生，状态就凝固了，不会再变了，会一直保持这个结果，这时就称为 resolved（已定型）。如果改变已经发生了，你再对`Promise`对象添加回调函数，也会立即得到这个结果。这与事件（Event）完全不同，事件的特点是，如果你错误了它，再去监听，是得不到结果的。

## 内容

- [基本用法](#一、基本用法)
- [then()](#二、then)
- [catch()](#三、catch)
- [finally()](#四、finally)
- [all()](#五、all)
- [ace()](#六、ace)
- [resolve()](#七、resolve)
- [reject()](#八、reject)
- [try()](#九、try)
- [应用](#十、应用)
- [错误用法及误区](#十一、错误用法及误区)
- [promise 你可能不知道的 6 件事](#十二、promise-你可能不知道的-6-件事)
- [手写 Promise](#十三、手写-promise)
- [Promise 几道面试题](##十四、promise-几道面试题)

### 一、基本用法

ES6 规定，`Promise`对象是一个构造函数，用来生成`Promise`实例。

```
const promise = new Promise(function(resolve,reject){

    if(/* 异步操作成功*/){
        resolve(value);
    }else{
        reject(error);
    }
})
```

`Promise` 构造函数接受一个函数作为参数，该函数的两个参数分别是 `resolve` 和 `reject`。

`resolve`函数的作用是，将`Promise`对象的状态从“未完成”变成“成功”（即从 pending 变成 resolved），在异步操作成功时调用，并将异步操作的结果，作为参数传递出去；

`reject`函数的作用是，将`Promse`对象的状态从“未完成”变为“失败”（即从 pending 变为 rejected），在异步操作失败时调用，并将异步操作报出的错误，作为参数传递出去。

### 二、then()

`then`方法是定义在原型对象`Promise.prototype`上的。`then`方法可以接受两个回调函数作为参数。第一个回调函数是`Promise`对象的状态变为`resolved`时调用。其中，第二个函数是可选的，不一定要提供。`then`方法返回的是一个新`Promise`实例。

```
getJSON("/post/1.json")
.then(post=>getJSON(post.commentURL))
.then(
    comments=>console.log("resolved:",comments),
    err=>console.log("rejected:",err)
);

```

### 三、catch()

`Promise.prototype.catch`方法是`.then(null, rejection)`的别名，用于指定发生错误时的回调函数。

- [基本用法](#31-基本用法)
- [Promise 的异常捕获方式](#32-promise-的异常捕获方式)

#### 3.1 基本用法

```
getJSON('/posts.json').then(function(posts) {
  // ...
}).catch(function(error) {
  // 处理 getJSON 和 前一个回调函数运行时发生的错误
  console.log('发生错误！', error);
});
```

上面代码中，`getJSON`方法返回一个`Promise`对象，如果该对象状态变为`resolved`，则会调用`then`方法指定的回调函数；如果异步操作抛出错误，状态就会变为`rejected`，就会调用`catch`方法指定的回调函数，处理这个错误。另外，`then`方法指定的回调函数，如果运行中抛出错误，也会被`catch`方法捕获。

```
var promise = new Promise(function(resolve, reject) {
  resolve('ok');
  throw new Error('test');
});
promise
  .then(function(value) { console.log(value) })
  .catch(function(error) { console.log(error) });
// ok
```

上面代码中，`Promise`在`resolve`语句后面，再抛出错误，不会被捕获，等于没有抛出。因为 `Promise`的状态一旦改变，就永久保持该状态，不会再变了。

#### 3.2 Promise 的异常捕获方式

- [在 Promise 的构造体内进行错误处理](#321-在-promise-的构造体内进行错误处理)
- [通过 Promise.prototype.catch 来进行错误处理](#322-通过-promiseprototypecatch-来进行错误处理)
- [Promise.all 中的异常捕获](#323-promiseall-中的异常捕获)
- [Promise.try 中的异常捕获](#324-promisetry-中的异常捕获)
- [在 Promise 中无法被捕获的错误](#325-在-promise-中无法被捕获的错误)

##### 3.2.1 在 Promise 的构造体内进行错误处理

```
var promise = new Promise(function(resolve,reject){
    try{
        throw new Error('test');
    }catch(e){
        reject(e)
    }
})
```

在 Promise 的构造体内进行错误处理，类似于我们在 ES5 中的错误处理方式。

##### 3.2.2 通过 Promise.prototype.catch 来进行错误处理

生成**Promise**实例后，我们可以通过**Promise**原型上的 catch 方法来捕获 Promise 实例内部的错误。`catch`方法返回的还是一个 Promise 对象。

```
var promise = new Promise(function(resolve,reject){
    reject(new Error('test'));
})

promise.catch(function(e){
    // something to deal with the error
    console.log(e);
})
```

此外 catch 方法还可以处理链式调用中的错误，比如：

```
var promise = new Promise(function(resolve,reject){
    resolve();
})
promise.then(function(){
    // if some error throw
}).then(function(){
    // if some error throw
}).catch(function(e){
    // something to deal with the error
    console.log(e)
})

// Error:test1

```

上述的代码，最后一个 catch 方法可以捕获前面链式调用过程中任何一步 then 方法里面所抛出的错误。catch 方面里面还可以再抛错误，这个错误会被后面的 catch 捕获

```
var promise = new Promise(function(resolve,reject){
    reject(new Error('test1'))
})
promise.catch(function(e){
    console.log(e);
    throw new Error('test2')
}).catch(function(e){
    console.log(e)
})

// Error:test1
// Error:test2
```

##### 3.2.3 Promise.all 中的异常捕获

如果组成**Promise.all**的**promise**有自己的错误捕获方法，那么**Promise.all**中的 catch 就不能捕获该错误。

```
var p1= new Promise(function(resolve,reject){
    reject(new Error('test1'));
}).catch(function(e){
    console.log('由p1自身捕获')
});

var p2= new Promise(function(resolve,reject){
    resolve();
})
var p = Promise.all([p1,p2]);
p.then(function(){

}).catch(function(e){
    // 在此处捕获不到p1中的error
    console.log(e)
})
// 由p1贴身捕获Error:test1

```

##### 3.2.4 Promise.try 中的异常捕获

ES2018 中可以通过**Promise.try**来同步处理，可能是异步也可能是同步的函数。

```
function f(){}
Promise.try(f);
console.log(2);

```

上述的方法，不管是同步还是异步，都会执行该方法，再输出 2.

在**Promise.try**的错误处理中，通过 catch 方法既可以捕获 f 是同步函数情况下的错误，也可以捕获 f 是异步函数下的错误。

```
function f(){

}

Promise.try(f).then(function(){

}).catch(function(e){

})
```

##### 3.2.5 在 Promise 中无法被捕获的错误

在**promise**实例**resolve**之后，错误无法被捕获。

```
var promise = new Promise(function(resolve,reject){
    resolve();
    throw new Error('test');    // 该错误无法被捕获
})
promise.then(function(){
//
}).then(function(e){
    console.log(e)
})
```

该错误可以用尾调用 resolve 来避免。

参考资料：[总结一下 ES6/ES7 中 promise、generator 和 async/await 中的异常捕获方法 ](https://github.com/forthealllight/blog/issues/16)

### 四、finally()

`finally`方法用于指定不管`Promise`对象最后状态如何，都会执行的操作。

```
promise.then(result=>{...}).catch(error=>{...}).finally(()=>{...});
```

不管`promise`最后的状态，在执行完`then`或`catch`指定的回调函数以后，都会执行`finally`方法指定的回调函数。

简单实现 finally

```
    Promise.prototype.finally = function(callback){
        let P = this.contructor;
        return this.then(
            value => P.resolve(callback()).then(()=>value),
            reason => P.resolve(callback()).then(()=>{throw reason})
        )
    }
```

### 五、all()

`Promise.all`方法用于将多个 Promise 实例，包装成一个新的 Promise 实例。`Promise.all`方法接受一个数组作为参数，`p1`、`p2`、`p3`都是`Promise`实例，如果不是就会先调`Promise.resolve`方法，再进一步处理。

```
var p = Promise.all([p1,p2,p3]);
```

p 的状态由`p1`、`p2`、`p3`决定，分成两种情况。

1. 只有`p1`、`p2`、`p3`的状态都变成`fulfilled`，`p`的状态才会变成`fulfilled`，此时`p1`、`p2`、`p3`返回值组成一个数组，传递给`p`的回调函数。
2. 只要`p1`、`p2`、`p3`之中有一个被`rejected`，`p`的状态就变成`rejected`，此时第一个被`reject`的实例的返回值，会传递给`p`的回调函数。

```
// 生成一个Promise对象的数组
var promises = [2, 3, 5, 7, 11, 13].map(function (id) {
  return getJSON('/post/' + id + ".json");
});

Promise.all(promises).then(function (posts) {
  // ...
}).catch(function(reason){
  // ...
});

```

### 六、ace()

`Promise.race`方法同样是将多个 Promise 实例，包装成一个新的 Promise 实例。

```
var p = Promise.race([p1,p2,p3]);
```

只要`p1`、`p2`、`p3`之中有一个实例率先改变状态，`p`的状态就跟着改变。那个率先改变的 Promise 实例的返回值，就传递给`p`的回调函数。

`Promise.race`方法的参数与`Promise.all`方法一样，如果不是`Promise`实例，就会先调用`Promise.resolve`方法，将参数转为`Promise`实例，再进一步处理。

```
const p = Promise.race([
  fetch('/resource-that-may-take-a-while'),
  new Promise(function (resolve, reject) {
    setTimeout(() => reject(new Error('request timeout')), 5000)
  })
]);
p.then(response => console.log(response));
p.catch(error => console.log(error));
```

### 七、resolve()

有时需要将现有对象转为 Promise 对象，`Promise.resolve`方法就赶到这个作用。

`Promise.resolve`等价于下面的写法。

```
Promise.resolve('foo')
//  等价于
new Promise(resolve=>resolve('foo'))
```

`resolve`方法的参数分成四种情况

1. 参数是一个 `Promise`实例
2. 参数是一个`thenable`对象
3. 参数不是具有`then`方法的对象，或根本就不是对象
4. 不带有任何参数

#### 7.1 参数是一个 `Promise`实例

如果参数是 Promise 实例，那么`Promise.resolve`将不做任何修改、原封不动地返回这个实例。

#### 7.2 参数是一个`thenable`对象

`thenable`对象指的是具有`then`方法的对象，`Promise.resolve`方法会将这个对象转为 Promise 对象，然后就立即执行`thenable`对象的`then`方法。

```
let thenable = {
    then: function(resolve,reject){
        resolve(42);
    }
};

let p1 = Promise.resolve(thenable);
p1.then(function(value){
    console.log(value);     // 42
})
```

`thenable`对象的`then`方法执行后，对象`p1`的状态就变为`resolved`，从而立即执行最后那个`then`方法指定的回调函数，输出 42。

#### 7.3 参数不是具有`then`方法的对象，或根本就不是对象

如果参数是一个原始值，或者是一个不具有`then`方法的对象，则`Promise.resolve`方法返回一个新的 Promise 对象，状态为`resolved`。

```
var p = Promise.resolve('Hello');

p.then(function (s){
  console.log(s)
});
// Hello
```

#### 7.4 不带有任何参数

`Promise.resolve`方法允许调用时不带参数，直接返回一个`resolved`状态的`Promise`对象。

### 八、reject()

`reject(reason)`方法也会返回一个新的`Promise`实例，该实例的状态为`rejected`。

```
var p = Promise.reject('出错了');

// 等同于
var p = new Promise((resolve,reject)=> reject('出错了'))

p.then(null,function(s){
    console.log(s)
})
// 出错了
```

### 九、try()

实际开发中，经常遇到一种情况：不知道或者不想区分，函数`f`是同步函数还是异步操作，但是想用 Promise 来处理它。因为这样就可以不管`f`是否饮食异步操作，都用`then`方法指定下一步流程，用`catch`方法处理`f`抛出的错误。

```
Promise.resolve().then(f)
```

上面的写法有一个缺点，就是如果 f 是同步函数，那么它会在本轮事件循环的末尾执行。

### 十、应用

- [加载图片](#101-加载图片)
- [通过 Promise 封装 ajax 解决回调地狱问题](#102-通过-promise-封装-ajax-解决回调地狱问题)
- [Generator 函数与 Promise 的结合](#103-generator-函数与-promise-的结合)

#### 10.1 加载图片

我们可以将图片的加载写成一个`Promise`，一旦加载完成，`Promise`的状态就发生变化。

```
const preloadImage = function(path){
    return new Promise(function(resolve,reject){
        var image = new Image();
        image.onload = resolve;
        image.onerror = reject;
        image.src = path;
    });
}
```

#### 10.2 通过 Promise 封装 ajax 解决回调地狱问题

```
function getJSON(url){
    return new Promise((resolve,reject) => {
        var XHR = new XMLHttpRequest();
        XHR.open('GET',url);
        client.onreadystatechange = handler;
        client.responseType = 'json';
        client.setRequestHeader('Accept','application/json');
        client.send();

        function handler(){
            if(this.readyState !==4){
                return;
            }
            if(this.status === 200){
                resolve(this.response);
            }else{
                reject(new Error(this.statusText));
            }
        };
    });

    return promise;
}
```

#### 10.3 Generator 函数与 Promise 的结合

使用`Generator`函数管理流程，遇到异步操作的时候，通常返回一个`Promise`对象。

```
function getFoo () {
  return new Promise(function (resolve, reject){
    resolve('foo');
  });
}

const g = function* () {
  try {
    const foo = yield getFoo();
    console.log(foo);
  } catch (e) {
    console.log(e);
  }
};

function run (generator) {
  const it = generator();

  function go(result) {
    if (result.done) return result.value;

    return result.value.then(function (value) {
      return go(it.next(value));
    }, function (error) {
      return go(it.throw(error));
    });
  }

  go(it.next());
}

run(g);
```

### 十一、错误用法及误区

- [当作回调来用 Callback Hell](#111-当作回调来用-callback-hell)
- [怎样用 forEach() 处理 promise](#112-怎样用-foreach-处理-promise)
- [没有返回值](#113-没有返回值)
- [没有 Catch](#114-没有-catch)
- [catch()与 then(null, fn)](#115-catch与-thennull-fn并不完全相同)
- [断链 The Broken Chain](#116-断链-the-broken-chain)
- [穿透 Fall Through](#117-穿透-fall-through)

#### 11.1 当作回调来用 Callback Hell

```
loadAsync1().then(function(data1){
    loadAsync2(data1).then(function(data2){
        loadAsync3(data2).then(okFn,failFn)
    });
});
```

Promise 用来解决异步嵌套回调的，这种写法虽然可靠，但违背了 Promise 的设计初衷改成下面的写法，会让结构更加清晰

```
loadAsync1().then(function(data1){
    return loadAsync2(data1)
}).then(function(data2){
    return loadAsync3(data2)
}).then(okFn,failFn)
```

#### 11.2 怎样用 forEach() 处理 promise

```
db.allDocs({include_docs:true}).then(function(result){
    result.rows.forEach(function(row){
        db.remove(row.doc);
    })
}).then(function(){

})
```

这段代码的问题在于第一个回调函数实际上返回的是`undefined`，也就意味着第二个函数并不是在所有的`db.remove()`执行结束之后才执行。

```
db.allDocs({include_docs:true}).then(function(result){
    return Promise.all(result.rows.map(function(row){
        return db.remove(row.doc);
    }))
}).then(function(arrayObject){
    // All docs have
})

```

从根本上说，`Promise.all()`以一个 promise 对象组成的数组为输入，返回另一个 promise 对象。

#### 11.3 没有返回值

```
loadAsync1().then(function(data1){
    loadAsync2(data1)
}).then(function(data2){
    loadAsync3(data2)
}).then(res=>console.log(res))
```

#### 11.4 没有 Catch

```
loadAsync1().then(function(data1){

}).then(function(data2){

}).then(okFn,failFn)
```

这里的调用，并没有添加 catch 方法，那么如果中间某个环节发生错误，将不会被捕获，控制台将看不到任何错误，不利于调试查错，所以最好在最后添加 catch 方法用于捕获错误。

```
loadAsync1()
    .then(function(data1){
        return loadAsync2(data1)
    })
    .then(function(data2){
        return loadAsync3(data2)
    }).then(okFn,failFn)
    .catch(err=>console.log(err))
```

#### 11.5 `catch()`与 `then(null, fn)`并不完全相同

```
somePromise().then(function () {
  throw new Error('oh noes');
}).catch(function (err) {
  // I caught your error! :)
});

somePromise().then(function () {
  throw new Error('oh noes');
}, function (err) {
  // I didn't catch your error! :(
});
```

当使用`then(resolveHandler,rejectHandler)`，`rejectHandler`不会捕获在`resolveHandler`中抛出的错误。

#### 11.6 断链 The Broken Chain

```
function loadAsyncFnX(){return Promise.resolve(1);}
function doSth(){return 2;}

function asyncFn(){
    var promise = loadAsyncFnx()
    promise.then(function(){
            reutrn doSth();
    })
    return promise;
}

asyncFn().then(res=>console.log(res)).catch(err=>console.log(err))      // 1
```

从执行结果来看，then 中架设的参数其实并不是 doSth()返回的结果，而是 loadAsyncFnX()返回的结果，catch 到的错误也是 loadAsyncFnX()中的错误，所以 doSth()的结果和错误将不会被后而的 then 中的回调捕获到，形成了断链，因为 then 方法将返回一个新的 Promise 对象，而不是原来的 Promise 对象

```
function loadAsyncFnX(){ return Promise.resolve(1); }
function doSth(){ return 2; }

function asyncFn(){
	var promise = loadAsyncFnX()
    return promise.then(function(){
		return doSth();
    })
}

asyncFn().then(res=>console.log(res)).catch(err=>console.log(err))
```

#### 11.7 穿透 Fall Through

```
Promise.resolve('foo').then(Promise.resolve('bar')).then(function(result){
    console.log(result);
})
```

如果你认为输出的是 bar，那么你就错了。实际上它输出的是 foo！

产生这样的输出是因为你给 then 方法传递了一个非函数的值，代码会这样理解：`then(null)`，因此导致前一个 promise 的结果产生了坠落的效果。

参考资料：[深入理解 Promise (上)](http://coderlt.coding.me/2016/12/03/promise-in-depth-an-introduction-1/)

### 十二、promise 你可能不知道的 6 件事

- [`then()`返回一个 forked Promise(分叉的 Promise)](#121-then返回一个-forked-promise分叉的-promise)
- [回调函数应该传递结果](#122-回调函数应该传递结果)
- [只能捕获来自上一级的异常](#123-只能捕获来自上一级的异常)
- [错误能被恢复](#124-错误能被恢复)
- [Promise 能被暂停](#125-promise-能被暂停)
- [resolved 状态的 Promise 不会立即执行](#126-resolved-状态的-promise-不会立即执行)

#### 12.1 `then()`返回一个 forked Promise(分叉的 Promise)

```
// Exhitbit A
var p = new Promise(/*...*/);
p.then(func1);
p.then(func2);
```

```
// Exhitbit B
var p = new Promise(/*...*/);
p.then(func1).then(func2);
```

如果你认为两段代码等价，那么你可能认为 promise 仅仅就是一维回调函数的数组。然而，这两段代码并不等价。`p`每次调用`then()`都会返回一个`forked promise`。因此，在 A 中，如果`func1`抛出一个异常，`func2`依然能执行，而在 B 中，`func2`不会被执行，因为第一次调用返回了一个新`promise`，由于`func1`中抛出异常，这个`promise`被`rejected`了，结果`func2`被跳过不执行了。

#### 12.2 回调函数应该传递结果

```
var p = new Promise(function(resolve,reject){
    resolve("hello world");
})

p.then(function(str){

}).then(function(str){
    console.log(str)
})
```

第二个`then()`中的`console.log`显示的是`undefined`，因为在 promise 的上下文中，回调函数像普通的回调函数一样传递结果。promise 期望你的回调函数或者返回同一个结果，或者返回其它结果，返回的结果会被传给下一个回调。

#### 12.3 只能捕获来自上一级的异常

```
new Promise(function(resolve,reject){
    resolve('hello world');
}).then(function(str){
    throw new Error('uh oh');
},undefined).then(undefined,function(error){
    console.log(error);
})
```

```
// Exhibit B
new Promise(function(resolve,reject){
    resolve('hello world');
}).then(function(str){
    throw new Error('uh oh');
},function(error){
    console.log(error);
});
```

在 A 中，当第一个`then`抛出异常时，第二个`then`能捕获到该异常，并会弹出`uh oh`。这符合只捕获来自上一级异常的规则。

在 B 中，正确的回调函数和错误的回调函数在同一级，也就是说，尽管在回调中抛出了异常，但是这个异常不会被捕获。事实上，B 中的错误回调只有在`promise`被`rejected`或者`promise`自身抛出一个异常时才会被执行。

#### 12.4 错误能被恢复

在一个错误回调中，如果没有重新抛出错误，promise 会认为你已经恢复了该错误，promise 的状态会转变为`resolved`。

```
var p = new Promise(function(resolve,reject){
    reject(new Error('pebkac'));
});

p.then(
    undefined,
    function(error){ }
)
 .then(
    function(str){
        alert('I am saved!');
    },
    function(error){
     alert('Bad computer!');
    }
);
```

#### 12.5 Promise 能被暂停

仅仅因为你已经在一个`then()`函数中执行过代码，并不意味着你不能够暂停 promise 去做其他事情。为了暂停当前的 promise，或者要它等待另一个 promise 完成，只需要简单地在 then() 函数中返回另一个 promise。

```
var p = new Promise(/*...*/);

p.then(function(str){
    if(!loggedIn){
        return new Promise(/*...*/);
    }
})
 .then(function(str){
    alert("Done!");
 });
```

在上面的代码中，直到新的`promise`的状态是`resolved`解析后，`alert`才会显示。如果要在已经存在的异步代码中引入更多的依赖，这是一个很便利的方式。例如，你发现用户会话已经超时了，因此，你可能想要在继续执行后面的代码之前发起第二次登录。

#### 12.6 resolved 状态的 Promise 不会立即执行

```
function runme() {
  var i = 0;

  new Promise(function(resolve) {
    resolve();
  })
  .then(function() {
    i += 2;
  });
  alert(i);
}
```

你可能会认为弹出 2，因为 promise 已经是 resolved ，then() 会立即执行(同步)。然而，promise 规范要求所有回调都是异步的，因此，alert 执行时 i 的值还没有被修改。

参考资料：[关于 Promise：你可能不知道的 6 件事](https://github.com/dwqs/blog/issues/1)

### 十三、手写 Promise

```
const PENDING = 'pending';
const FULFILLED = 'fulfilled';
const REJECTED = 'rejected';

function Promise(excutor){
    let that = this;        // 缓存当前promise实例对象
    that.status = PENDING;  // 初始状态
    that.value = undefined;     // fulfilled状态时 返回的信息
    that.reason = undefined;    // rejected状态时，拒绝的原因
    that.onFulfilledCallbacks = []; // 存储fulfilled状态对应的onFulfilled函数
    that.onRejectedCallbacks = [];      //存储rejected状态对应的onRejected函数

    function resolve(value){    // value成功态时接收的终值
        if(value instanceof Promise){
            return value.then(resolve,reject);
        }
        //  实践中要确保onFulfilled 和 onRejected方法异步执行，且应该在then方法被调用的那一轮事件循环之后的新执行栈中执行。
        setTimeout(()=>{
            //调用resolve回调对应onFulfilled函数
            if(that.status === PENDING){
                // 只能由pending状态=> fullfilled状态（避免调用多次resolve reject）
                that.status = FULFILLED;
                that.value = value;
                that.onFulfilledCallbacks.forEach(cb=>cb(that.value));
            }
        })
    }
    function reject(reason){    // reason失败态时接收的拒因
        setTimeout(()=>{
            // 调用reject 回调对应onRejected函数
            if (that.status === PENDING){
                // 只能由pending状态 => rejected状态（避免调用多次resolve reject）
                that.status = REJECTED;
                that.reason = reason;
                that.onRejectedCallbacks.forEach(cb=>cb(that.reason));
            }
        });
    }

    // 捕获在excutor执行器中抛出异常
    // new Promise((resolve,reject)=>{
        //   throw new Error('error in excutor')
    // })

    try{
        excutor(resolve,reject);
    }catch(e){
        reject(e);
    }
}

function resolvePromise(promise2,x,resolve,reject){
    var then;
    var thenCalledThrow = false;

    if(promise2 === x){
        return reject(new TypeError('Chaining cycle detected for promise!'))
    }

    if( x instanceof Promise){
        if(x.status === 'pending'){
            x.then(function(v){
                resolvePromise(promise2,v,resolve,reject)
            },reject)
        }else{
            x.then(resolve,reject)
        }
        return
    }

    if((x!==null) && ((typeof x=== 'object') || (typeof x === 'function'))){
        try{
            then = x.then   // because x.then could be a getter
            if(typeof then === 'function'){
                then.call(x,function rs(y){
                    if(thenCalledOrThrow) return
                    thenCalledOrThrow = true
                    reutrn resolvePromise(promise2,y,resolve,reject)
                },function rj(r){
                    if(thenCalledOrThrow) return
                    thenCalledOrThrow = true
                    return reject(r)
                })
            }else{
                resolve(x)
            }
        }catch(e){
            if(thenCalledOrThrow) return
            thenCalledOrThrow = true
            return reject(e)
        }
    }else{
        resolve(x)
    }
}

Promise.prototype.then = function(onFulfilled,onRejected){
    const that = this;
    let newPromise;
    // 处理参数默认值  保证参数后续能够继续执行
    onFulfilled = typeof onFulfilled === "function" ? onFulfilled : value => value;
    onRejected = typeof onRejected === 'function' ? onRejected : reason => {
        throw reason;
    }
    if ( that.status === FULFILLED){    //成功态
        return newPromise = new Promise((resolve,reject) =>{
            setTimeout(()=>{
                try{
                    let x = onFulfilled(that.value);
                    resolvePromise(newPromise,x,resolve,reject);
// 新的promise resolve 上一个onFulfilled的返回值
                }catch(e){
                    reject(e);  //  捕获前面onFulfilled中抛出的异常 then(onFulfilled, onRejected);
                }
            })
        })
    }

    if(that.status === REJECTED){   // 失败态
        return newPromise = new Promise((resolve,reject)=>{
            setTimeout(()=>{
                try{
                    let x = onRejected(that.reason);
                    resolvePromise(newPromise,x,resolve,reject);
                }catch(e){
                    reject(e);
                }
            })
        })
    }

    if(that.status === PENDING){    // 等待态
        // 当异步调用resolve/rejected时 将onFulfilled/onRejected收集暂存到集合中
        return newPromise = new Promise((resolve,reject)=>{
            that.onFulfilledCallbacks.push((value)=>{
                try{
                    let x = onFulfilled(value);
                    resolvePromise(newPromise,x,resolve,reject);
                }catch(e){
                    reject(e);
                }
            });
            that.onRejectedCallbacks.push((reason)=>{
                try{
                    let x = onRejected(reason);
                    reasolvePromise(newPromise,x,resolve,reject);
                }catch(e){
                    reject(e);
                }
            })
        })
    }
}

Promise.prototype.catch = function(onRejected){
    return thsi.then(null,onRejected)
}

Promise.deferred = Promise.defer = function(){
    var dfd ={}
    dfd.promise = new Promise(function(resolve,reject){
        dfd.resolve = resolve
        dfd.reject = reject
    })
    return dfd;
}

Promise.all = function(promises){
    return new Promise((resolve,reject){
        const result = []
        let cnt = 0
        for (let i = 0; i < promises.length;++i){
            promises[i].then(value=>{
                cnt++
                result[i]=value
                if(cnt  === promises.length) resolve(result)
            },reject)
        }
    })
}

Promise.race = function(promises){
    return new Promise((resolve,reject)=>{
        promises[i].then(resolve,reject)
    })
}

```

参考资料：

- [手写 promise](https://github.com/xieranmaya/blog/issues/3)
- [BAT 前端经典面试问题：史上最最最详细的手写 Promise 教程](https://juejin.im/post/5b2f02cd5188252b937548ab)
- [Promise 原理讲解 && 实现一个 Promise 对象 ](https://juejin.im/post/5aa7868b6fb9a028dd4de672)

### 十四、Promise 几道面试题

- [题目一](#141-题目一)
- [题目二](#142-题目二)
- [题目三](#143-题目三)
- [题目四](#144-题目四)
- [题目五](#145-题目五)
- [题目六](#146-题目六)
- [题目七](#147-题目七)
- [题目八](#148-题目八)
- [题目九](#149-题目九)
- [题目十](#1410-题目十)

#### 14.1 题目一

```
const promise = new Promise((resolve,reject)=>{
    console.log(1)
    resolve()
    console.log(2)
})
promise.then(()=>{
    console.log(3)
})
console.log(4)
```

#### 14.2 题目二

```
const promise1 = new Promise(resolve,reject)=>{
    setTimeout(()=>{
        resolve('success')
    },1000)
})
const promise2 = promise1.then(()=>{
    throw new Error('error!!!')
})

console.log('promise1',promise1)
console.log('promise2',promise2)

setTimeout(()=>{
    console.log('promise1',promise1)
    console.log('promise2',promise2)
},2000)
```

#### 14.3 题目三

```
const promise = new Promise((resolve,reject)=>{
    resolve('success1')
    reject('error')
    resolve('success2')
})

promise.then((res)=>{
    console.log('then:',res)
}).catch((err)=>{
    console.log('catch:',err)
})
```

#### 14.4 题目四

```
Promise.resolve(1).then((res)=>{
    console.log(res)
    return 2
}).catch((err)=>{
    return 3
}).then((res)=>{
    console.log(res)
})
```

#### 14.5 题目五

```
const promise = new Promise((resolve,reject)=>{
    setTimeout(()=>{
        console.log('once')
        resolve('success')
    },1000)
})

const start = Date.now()
promise.then((res)=>{
    console.log(res,Date.now()-start)
})
promise.then((res)=>{
    console.log(res,Date.now()-start)
})
```

#### 14.6 题目六

```
Promise.resolve().then(()=>{
    return new Error('error!!')
}).then((res)=>{
    console.log('then:',res)
}).catch((err)=>[
    cosnole.log('catch:',err)
])
```

#### 14.7 题目七

```
const promise = Promise.resolve().then(()=>{
    return promise
})
promise.catch(console.error)
```

#### 14.8 题目八

```
Promise.resolve(1).then(2).then(Promise.resolve(3)).then(console.log)
```

#### 14.9 题目九

```
Promise.resolve().then(function(res){
    throw new Error('error')
},function (e){
    console.log(e)
}).catch((e)=>{
    console.log('fail:',e)
})
```

#### 14.10 题目十

```
process.nextTick(()=>{
    console.log('nextTick')
})
Promise.resolve().then(()=>{
    console.log('then')
})
setImmediate(()=>{
    console.log('setImmediate')
})
console.log('end')
```

- [Promise 必知必会（十道题）](https://juejin.im/post/5a04066351882517c416715d)
- [【建议星星】要就来 45 道 Promise 面试题一次爽到底(1.1w 字用心整理)](https://juejin.im/post/5e58c618e51d4526ed66b5cf)

### 参考资料

- [Promise A+ 规范](https://malcolmyu.github.io/2015/06/12/Promises-A-Plus/)
- [JavaScript Promise 迷你书](http://liubin.org/promises-book/)
- [你了解 Promise 吗？](https://mp.weixin.qq.com/s/mvqR4oEq1VcTYB57QqGIvQ)
- [promise 是什么？](https://mp.weixin.qq.com/s/0DVOqFQYSzCaviSv_3AF-g)
- [100 行代码实现 Promises/A+ 规范](https://zhuanlan.zhihu.com/p/83965949)
- [《ECMAScript 6 入门》 第三版](https://yjhenan.gitbooks.io/-ecmascript-6/content/docs/promise.html)
- [ECMAScript 6 入门](http://es6.ruanyifeng.com/#docs/promise)
- [JS 高级之手写一个 Promise,Generator,async 和 await【近 1W 字】](https://juejin.im/post/5df83b93f265da33f8652ccc)
- [细说 JS 异步发展历程](https://juejin.im/post/5ce40e5ee51d4556be5b39b7)
- [马蹄疾 | 详解 JavaScript 异步机制及发展历程(万字长文)](https://juejin.im/post/5cda1492e51d453a8f348c02)
- [【建议星星】要就来 45 道 Promise 面试题一次爽到底(1.1w 字用心整理)](https://juejin.im/post/5e58c618e51d4526ed66b5cf)
- [Promise / async / Generator 实现&原理大解析（附源码）| 9k 字](https://juejin.im/post/5e3b9ae26fb9a07ca714a5cc)
- [源码速读！一看就会、一写就废的 Promise 实现](https://mp.weixin.qq.com/s/CsUvmRLYJpX1If9Tr0KXrg)
- [Promise 你真的用明白了么？](https://juejin.im/post/6869573288478113799)
- 《你不知道的 javascript(中)》
- 《深入浅出 Node.js》

## 联系作者

<div align="center">
    <p>
        平凡世界，贵在坚持。
    </p>
    <img :src="$withBase('/about/contact.png')" />
</div>
